2023-05-16 10:12:05.756219: You've used an invalid search string. Try again.1064 people_filtered
2023-05-16 10:14:36.556943: You've used an invalid search string. Try again.1064 people_filtered
2023-05-16 10:16:54.983427: ("'Person' object has no attribute 'instanceoflabel'",)'Person' object has no attribute 'instanceoflabel' graph.load_graph
2023-05-16 10:16:54.983675: ('string indices must be integers',)string indices must be integers corpbodies_filtered
2023-05-16 10:17:49.583441: ("'Person' object has no attribute 'instanceoflabel'",)'Person' object has no attribute 'instanceoflabel' graph.load_graph
2023-05-16 10:17:49.583661: ('string indices must be integers',)string indices must be integers corpbodies_filtered
2023-05-16 10:17:54.501759: ("'Person' object has no attribute 'instanceoflabel'",)'Person' object has no attribute 'instanceoflabel' graph.load_graph
2023-05-16 10:17:54.501883: ('string indices must be integers',)string indices must be integers corpbodies_filtered
2023-05-16 11:40:38.618848: ("'Person' object has no attribute 'instanceoflabel'",)'Person' object has no attribute 'instanceoflabel' graph.load_graph
2023-05-16 11:40:38.619232: ('string indices must be integers',)string indices must be integers corpbodies_filtered
2023-05-16 14:25:40.382926: ("'Collection' object has no attribute 'instanceoflabel'",)'Collection' object has no attribute 'instanceoflabel' graph.load_graph
2023-05-16 14:25:40.383305: ('string indices must be integers',)string indices must be integers corpbodies_filtered
2023-05-17 09:30:02.116180: You've used an invalid search string. Try again.1064 corpbodies_filtered
2023-05-17 09:31:10.969505: You've used an invalid search string. Try again.1064 people_filtered
2023-05-17 09:31:37.141709: You've used an invalid search string. Try again.1064 people_filtered
2023-05-17 09:31:55.532308: You've used an invalid search string. Try again.1064 people_filtered
Invalid HTTP_HOST header: '131.216.162.49'. You may need to add '131.216.162.49' to ALLOWED_HOSTS.
Traceback (most recent call last):
  File "/data/www/wikidataDiscovery/wd_venv/lib/python3.10/site-packages/django/core/handlers/exception.py", line 56, in inner
    response = get_response(request)
  File "/data/www/wikidataDiscovery/wd_venv/lib/python3.10/site-packages/django/utils/deprecation.py", line 135, in __call__
    response = self.process_request(request)
  File "/data/www/wikidataDiscovery/wd_venv/lib/python3.10/site-packages/django/middleware/common.py", line 48, in process_request
    host = request.get_host()
  File "/data/www/wikidataDiscovery/wd_venv/lib/python3.10/site-packages/django/http/request.py", line 152, in get_host
    raise DisallowedHost(msg)
django.core.exceptions.DisallowedHost: Invalid HTTP_HOST header: '131.216.162.49'. You may need to add '131.216.162.49' to ALLOWED_HOSTS.
2023-05-19 09:39:12.143213: You've used an invalid search string. Try again.1064 corpbodies_filtered
2023-05-19 09:39:14.994165: You've used an invalid search string. Try again.1064 corpbodies_filtered
2023-05-19 09:39:49.545022: ("'CorpBody' object has no attribute 'image'",)'CorpBody' object has no attribute 'image' graph.load_graph
2023-05-19 09:39:49.545285: ('string indices must be integers',)string indices must be integers people_filtered
2023-05-19 09:40:16.770045: You've used an invalid search string. Try again.1064 people_filtered
2023-05-19 09:42:05.286171: ("'CorpBody' object has no attribute 'image'",)'CorpBody' object has no attribute 'image' graph.load_graph
2023-05-19 09:42:05.286398: ('string indices must be integers',)string indices must be integers people_filtered
2023-05-19 09:51:00.210367: You've used an invalid search string. Try again.1064 collections_filtered
2023-05-19 14:21:11.333206: ("'Person' object has no attribute 'instanceoflabel'",)'Person' object has no attribute 'instanceoflabel' graph.load_graph
2023-05-19 14:21:11.333739: ('string indices must be integers',)string indices must be integers corpbodies_filtered
2023-05-22 09:43:05.271536: You've used an invalid search string. Try again.1064 corpbodies_filtered
2023-05-22 10:03:47.030507: You've used an invalid search string. Try again.1064 corpbodies_filtered
2023-05-22 10:14:47.293539: You've used an invalid search string. Try again.1064 collections_filtered
2023-05-22 10:16:46.298568: ("'Collection' object has no attribute 'image'",)'Collection' object has no attribute 'image' graph.load_graph
2023-05-22 10:16:46.298828: ('string indices must be integers',)string indices must be integers people_filtered
2023-05-22 13:28:57.734796: ("'Collection' object has no attribute 'image'",)'Collection' object has no attribute 'image' graph.load_graph
2023-05-22 13:28:57.735142: ('string indices must be integers',)string indices must be integers people_filtered
2023-05-22 13:40:49.914232: ("'Collection' object has no attribute 'image'",)'Collection' object has no attribute 'image' graph.load_graph
2023-05-22 13:40:49.914457: ('string indices must be integers',)string indices must be integers people_filtered
Invalid HTTP_HOST header: 'wikiframe.library.unlv.edu'. You may need to add 'wikiframe.library.unlv.edu' to ALLOWED_HOSTS.
Traceback (most recent call last):
  File "/data/www/wikidataDiscovery/wd_venv/lib/python3.10/site-packages/django/core/handlers/exception.py", line 56, in inner
    response = get_response(request)
  File "/data/www/wikidataDiscovery/wd_venv/lib/python3.10/site-packages/django/utils/deprecation.py", line 135, in __call__
    response = self.process_request(request)
  File "/data/www/wikidataDiscovery/wd_venv/lib/python3.10/site-packages/django/middleware/common.py", line 48, in process_request
    host = request.get_host()
  File "/data/www/wikidataDiscovery/wd_venv/lib/python3.10/site-packages/django/http/request.py", line 152, in get_host
    raise DisallowedHost(msg)
django.core.exceptions.DisallowedHost: Invalid HTTP_HOST header: 'wikiframe.library.unlv.edu'. You may need to add 'wikiframe.library.unlv.edu' to ALLOWED_HOSTS.
Invalid HTTP_HOST header: 'wikiframe.library.unlv.edu'. You may need to add 'wikiframe.library.unlv.edu' to ALLOWED_HOSTS.
Traceback (most recent call last):
  File "/data/www/wikidataDiscovery/wd_venv/lib/python3.10/site-packages/django/core/handlers/exception.py", line 56, in inner
    response = get_response(request)
  File "/data/www/wikidataDiscovery/wd_venv/lib/python3.10/site-packages/django/utils/deprecation.py", line 135, in __call__
    response = self.process_request(request)
  File "/data/www/wikidataDiscovery/wd_venv/lib/python3.10/site-packages/django/middleware/common.py", line 48, in process_request
    host = request.get_host()
  File "/data/www/wikidataDiscovery/wd_venv/lib/python3.10/site-packages/django/http/request.py", line 152, in get_host
    raise DisallowedHost(msg)
django.core.exceptions.DisallowedHost: Invalid HTTP_HOST header: 'wikiframe.library.unlv.edu'. You may need to add 'wikiframe.library.unlv.edu' to ALLOWED_HOSTS.
2023-05-24 09:16:32.909642: You've used an invalid search string. Try again.1064 corpbodies_filtered
2023-05-24 09:24:53.030088: You've used an invalid search string. Try again.1064 corpbodies_filtered
2023-05-24 09:26:53.497947: ("'CorpBody' object has no attribute 'donatedbylabel'",)'CorpBody' object has no attribute 'donatedbylabel' graph.load_graph
2023-05-24 09:26:53.498220: ('string indices must be integers',)string indices must be integers collections_filtered
2023-05-30 09:57:44.378164: You've used an invalid search string. Try again.1064 corpbodies_filtered
Invalid HTTP_HOST header: 'wikiframe.library.unlv.edu'. You may need to add 'wikiframe.library.unlv.edu' to ALLOWED_HOSTS.
Traceback (most recent call last):
  File "/data/www/wikidataDiscovery/wd_venv/lib/python3.10/site-packages/django/core/handlers/exception.py", line 56, in inner
    response = get_response(request)
  File "/data/www/wikidataDiscovery/wd_venv/lib/python3.10/site-packages/django/utils/deprecation.py", line 135, in __call__
    response = self.process_request(request)
  File "/data/www/wikidataDiscovery/wd_venv/lib/python3.10/site-packages/django/middleware/common.py", line 48, in process_request
    host = request.get_host()
  File "/data/www/wikidataDiscovery/wd_venv/lib/python3.10/site-packages/django/http/request.py", line 152, in get_host
    raise DisallowedHost(msg)
django.core.exceptions.DisallowedHost: Invalid HTTP_HOST header: 'wikiframe.library.unlv.edu'. You may need to add 'wikiframe.library.unlv.edu' to ALLOWED_HOSTS.
Invalid HTTP_HOST header: 'wikiframe.library.unlv.edu'. You may need to add 'wikiframe.library.unlv.edu' to ALLOWED_HOSTS.
Traceback (most recent call last):
  File "/data/www/wikidataDiscovery/wd_venv/lib/python3.10/site-packages/django/core/handlers/exception.py", line 56, in inner
    response = get_response(request)
  File "/data/www/wikidataDiscovery/wd_venv/lib/python3.10/site-packages/django/utils/deprecation.py", line 135, in __call__
    response = self.process_request(request)
  File "/data/www/wikidataDiscovery/wd_venv/lib/python3.10/site-packages/django/middleware/common.py", line 48, in process_request
    host = request.get_host()
  File "/data/www/wikidataDiscovery/wd_venv/lib/python3.10/site-packages/django/http/request.py", line 152, in get_host
    raise DisallowedHost(msg)
django.core.exceptions.DisallowedHost: Invalid HTTP_HOST header: 'wikiframe.library.unlv.edu'. You may need to add 'wikiframe.library.unlv.edu' to ALLOWED_HOSTS.
2023-05-30 10:07:26.826070: You've used an invalid search string. Try again.1064 collections_filtered
2023-05-30 10:17:28.057886: ("'Collection' object has no attribute 'image'",)'Collection' object has no attribute 'image' graph.load_graph
2023-05-30 10:17:28.058126: ('string indices must be integers',)string indices must be integers people_filtered
Invalid HTTP_HOST header: 'wikiframe.library.unlv.edu'. You may need to add 'wikiframe.library.unlv.edu' to ALLOWED_HOSTS.
Traceback (most recent call last):
  File "/data/www/wikidataDiscovery/wd_venv/lib/python3.10/site-packages/django/core/handlers/exception.py", line 56, in inner
    response = get_response(request)
  File "/data/www/wikidataDiscovery/wd_venv/lib/python3.10/site-packages/django/utils/deprecation.py", line 135, in __call__
    response = self.process_request(request)
  File "/data/www/wikidataDiscovery/wd_venv/lib/python3.10/site-packages/django/middleware/common.py", line 48, in process_request
    host = request.get_host()
  File "/data/www/wikidataDiscovery/wd_venv/lib/python3.10/site-packages/django/http/request.py", line 152, in get_host
    raise DisallowedHost(msg)
django.core.exceptions.DisallowedHost: Invalid HTTP_HOST header: 'wikiframe.library.unlv.edu'. You may need to add 'wikiframe.library.unlv.edu' to ALLOWED_HOSTS.
Invalid HTTP_HOST header: 'wikiframe.library.unlv.edu'. You may need to add 'wikiframe.library.unlv.edu' to ALLOWED_HOSTS.
Traceback (most recent call last):
  File "/data/www/wikidataDiscovery/wd_venv/lib/python3.10/site-packages/django/core/handlers/exception.py", line 56, in inner
    response = get_response(request)
  File "/data/www/wikidataDiscovery/wd_venv/lib/python3.10/site-packages/django/utils/deprecation.py", line 135, in __call__
    response = self.process_request(request)
  File "/data/www/wikidataDiscovery/wd_venv/lib/python3.10/site-packages/django/middleware/common.py", line 48, in process_request
    host = request.get_host()
  File "/data/www/wikidataDiscovery/wd_venv/lib/python3.10/site-packages/django/http/request.py", line 152, in get_host
    raise DisallowedHost(msg)
django.core.exceptions.DisallowedHost: Invalid HTTP_HOST header: 'wikiframe.library.unlv.edu'. You may need to add 'wikiframe.library.unlv.edu' to ALLOWED_HOSTS.
Invalid HTTP_HOST header: 'wikiframe.library.unlv.edu'. You may need to add 'wikiframe.library.unlv.edu' to ALLOWED_HOSTS.
Traceback (most recent call last):
  File "/data/www/wikidataDiscovery/wd_venv/lib/python3.10/site-packages/django/core/handlers/exception.py", line 56, in inner
    response = get_response(request)
  File "/data/www/wikidataDiscovery/wd_venv/lib/python3.10/site-packages/django/utils/deprecation.py", line 135, in __call__
    response = self.process_request(request)
  File "/data/www/wikidataDiscovery/wd_venv/lib/python3.10/site-packages/django/middleware/common.py", line 48, in process_request
    host = request.get_host()
  File "/data/www/wikidataDiscovery/wd_venv/lib/python3.10/site-packages/django/http/request.py", line 152, in get_host
    raise DisallowedHost(msg)
django.core.exceptions.DisallowedHost: Invalid HTTP_HOST header: 'wikiframe.library.unlv.edu'. You may need to add 'wikiframe.library.unlv.edu' to ALLOWED_HOSTS.
Invalid HTTP_HOST header: 'wikiframe.library.unlv.edu'. You may need to add 'wikiframe.library.unlv.edu' to ALLOWED_HOSTS.
Traceback (most recent call last):
  File "/data/www/wikidataDiscovery/wd_venv/lib/python3.10/site-packages/django/core/handlers/exception.py", line 56, in inner
    response = get_response(request)
  File "/data/www/wikidataDiscovery/wd_venv/lib/python3.10/site-packages/django/utils/deprecation.py", line 135, in __call__
    response = self.process_request(request)
  File "/data/www/wikidataDiscovery/wd_venv/lib/python3.10/site-packages/django/middleware/common.py", line 48, in process_request
    host = request.get_host()
  File "/data/www/wikidataDiscovery/wd_venv/lib/python3.10/site-packages/django/http/request.py", line 152, in get_host
    raise DisallowedHost(msg)
django.core.exceptions.DisallowedHost: Invalid HTTP_HOST header: 'wikiframe.library.unlv.edu'. You may need to add 'wikiframe.library.unlv.edu' to ALLOWED_HOSTS.
Internal Server Error: /discover/people/
Traceback (most recent call last):
  File "/usr/local/lib/python3.10/dist-packages/django/core/handlers/exception.py", line 56, in inner
    response = get_response(request)
  File "/usr/local/lib/python3.10/dist-packages/django/core/handlers/base.py", line 197, in _get_response
    response = wrapped_callback(request, *callback_args, **callback_kwargs)
  File "/home/ed/PycharmProjects/wikidataDiscovery/discover/views.py", line 31, in people
    sform = forms.SearchForm()
  File "/home/ed/PycharmProjects/wikidataDiscovery/discover/forms.py", line 9, in __init__
    facet_val = kwargs['initial']
KeyError: 'initial'
"GET /discover/people/ HTTP/1.1" 500 80350
Internal Server Error: /discover/people/
Traceback (most recent call last):
  File "/usr/local/lib/python3.10/dist-packages/django/core/handlers/exception.py", line 56, in inner
    response = get_response(request)
  File "/usr/local/lib/python3.10/dist-packages/django/core/handlers/base.py", line 197, in _get_response
    response = wrapped_callback(request, *callback_args, **callback_kwargs)
  File "/home/ed/PycharmProjects/wikidataDiscovery/discover/views.py", line 38, in people
    return render(request, 'discover/base_people.html', context)
  File "/usr/local/lib/python3.10/dist-packages/django/shortcuts.py", line 24, in render
    content = loader.render_to_string(template_name, context, request, using=using)
  File "/usr/local/lib/python3.10/dist-packages/django/template/loader.py", line 62, in render_to_string
    return template.render(context, request)
  File "/usr/local/lib/python3.10/dist-packages/django/template/backends/django.py", line 61, in render
    return self.template.render(context)
  File "/usr/local/lib/python3.10/dist-packages/django/template/base.py", line 175, in render
    return self._render(context)
  File "/usr/local/lib/python3.10/dist-packages/django/template/base.py", line 167, in _render
    return self.nodelist.render(context)
  File "/usr/local/lib/python3.10/dist-packages/django/template/base.py", line 1005, in render
    return SafeString("".join([node.render_annotated(context) for node in self]))
  File "/usr/local/lib/python3.10/dist-packages/django/template/base.py", line 1005, in <listcomp>
    return SafeString("".join([node.render_annotated(context) for node in self]))
  File "/usr/local/lib/python3.10/dist-packages/django/template/base.py", line 966, in render_annotated
    return self.render(context)
  File "/usr/local/lib/python3.10/dist-packages/django/template/loader_tags.py", line 157, in render
    return compiled_parent._render(context)
  File "/usr/local/lib/python3.10/dist-packages/django/template/base.py", line 167, in _render
    return self.nodelist.render(context)
  File "/usr/local/lib/python3.10/dist-packages/django/template/base.py", line 1005, in render
    return SafeString("".join([node.render_annotated(context) for node in self]))
  File "/usr/local/lib/python3.10/dist-packages/django/template/base.py", line 1005, in <listcomp>
    return SafeString("".join([node.render_annotated(context) for node in self]))
  File "/usr/local/lib/python3.10/dist-packages/django/template/base.py", line 966, in render_annotated
    return self.render(context)
  File "/usr/local/lib/python3.10/dist-packages/django/template/loader_tags.py", line 63, in render
    result = block.nodelist.render(context)
  File "/usr/local/lib/python3.10/dist-packages/django/template/base.py", line 1005, in render
    return SafeString("".join([node.render_annotated(context) for node in self]))
  File "/usr/local/lib/python3.10/dist-packages/django/template/base.py", line 1005, in <listcomp>
    return SafeString("".join([node.render_annotated(context) for node in self]))
  File "/usr/local/lib/python3.10/dist-packages/django/template/base.py", line 966, in render_annotated
    return self.render(context)
  File "/usr/local/lib/python3.10/dist-packages/django/template/base.py", line 1070, in render
    return render_value_in_context(output, context)
  File "/usr/local/lib/python3.10/dist-packages/django/template/base.py", line 1047, in render_value_in_context
    value = str(value)
  File "/usr/local/lib/python3.10/dist-packages/django/forms/utils.py", line 75, in render
    return mark_safe(renderer.render(template, context))
  File "/usr/local/lib/python3.10/dist-packages/django/forms/renderers.py", line 29, in render
    return template.render(context, request=request).strip()
  File "/usr/local/lib/python3.10/dist-packages/django/template/backends/django.py", line 61, in render
    return self.template.render(context)
  File "/usr/local/lib/python3.10/dist-packages/django/template/base.py", line 175, in render
    return self._render(context)
  File "/usr/local/lib/python3.10/dist-packages/django/template/base.py", line 167, in _render
    return self.nodelist.render(context)
  File "/usr/local/lib/python3.10/dist-packages/django/template/base.py", line 1005, in render
    return SafeString("".join([node.render_annotated(context) for node in self]))
  File "/usr/local/lib/python3.10/dist-packages/django/template/base.py", line 1005, in <listcomp>
    return SafeString("".join([node.render_annotated(context) for node in self]))
  File "/usr/local/lib/python3.10/dist-packages/django/template/base.py", line 966, in render_annotated
    return self.render(context)
  File "/usr/local/lib/python3.10/dist-packages/django/template/loader_tags.py", line 208, in render
    return template.render(context)
  File "/usr/local/lib/python3.10/dist-packages/django/template/base.py", line 177, in render
    return self._render(context)
  File "/usr/local/lib/python3.10/dist-packages/django/template/base.py", line 167, in _render
    return self.nodelist.render(context)
  File "/usr/local/lib/python3.10/dist-packages/django/template/base.py", line 1005, in render
    return SafeString("".join([node.render_annotated(context) for node in self]))
  File "/usr/local/lib/python3.10/dist-packages/django/template/base.py", line 1005, in <listcomp>
    return SafeString("".join([node.render_annotated(context) for node in self]))
  File "/usr/local/lib/python3.10/dist-packages/django/template/base.py", line 966, in render_annotated
    return self.render(context)
  File "/usr/local/lib/python3.10/dist-packages/django/template/defaulttags.py", line 238, in render
    nodelist.append(node.render_annotated(context))
  File "/usr/local/lib/python3.10/dist-packages/django/template/base.py", line 966, in render_annotated
    return self.render(context)
  File "/usr/local/lib/python3.10/dist-packages/django/template/base.py", line 1070, in render
    return render_value_in_context(output, context)
  File "/usr/local/lib/python3.10/dist-packages/django/template/base.py", line 1047, in render_value_in_context
    value = str(value)
  File "/usr/local/lib/python3.10/dist-packages/django/utils/html.py", line 419, in <lambda>
    klass.__str__ = lambda self: mark_safe(klass_str(self))
  File "/usr/local/lib/python3.10/dist-packages/django/forms/boundfield.py", line 34, in __str__
    return self.as_widget()
  File "/usr/local/lib/python3.10/dist-packages/django/forms/boundfield.py", line 94, in as_widget
    attrs = self.build_widget_attrs(attrs, widget)
  File "/usr/local/lib/python3.10/dist-packages/django/forms/boundfield.py", line 261, in build_widget_attrs
    widget.use_required_attribute(self.initial)
  File "/usr/local/lib/python3.10/dist-packages/django/utils/functional.py", line 57, in __get__
    res = instance.__dict__[self.name] = self.func(instance)
  File "/usr/local/lib/python3.10/dist-packages/django/forms/boundfield.py", line 255, in initial
    return self.form.get_initial_for_field(self.field, self.name)
  File "/usr/local/lib/python3.10/dist-packages/django/forms/forms.py", line 524, in get_initial_for_field
    value = self.initial.get(field_name, field.initial)
AttributeError: 'str' object has no attribute 'get'
"GET /discover/people/ HTTP/1.1" 500 286884
2023-06-05 09:38:49.203929: ('can only concatenate str (not "NoneType") to str',)can only concatenate str (not "NoneType") to str corpbodies_filtered
Internal Server Error: /discover/testy_processed/
Traceback (most recent call last):
  File "/home/ed/PycharmProjects/wikidataDiscovery/wd_venv/lib/python3.10/site-packages/django/core/handlers/exception.py", line 56, in inner
    response = get_response(request)
  File "/home/ed/PycharmProjects/wikidataDiscovery/wd_venv/lib/python3.10/site-packages/django/core/handlers/base.py", line 197, in _get_response
    response = wrapped_callback(request, *callback_args, **callback_kwargs)
  File "/home/ed/PycharmProjects/wikidataDiscovery/discover/views.py", line 32, in testy_processed
    if lf.is_valid():
  File "/home/ed/PycharmProjects/wikidataDiscovery/wd_venv/lib/python3.10/site-packages/django/forms/forms.py", line 205, in is_valid
    return self.is_bound and not self.errors
  File "/home/ed/PycharmProjects/wikidataDiscovery/wd_venv/lib/python3.10/site-packages/django/forms/forms.py", line 200, in errors
    self.full_clean()
  File "/home/ed/PycharmProjects/wikidataDiscovery/wd_venv/lib/python3.10/site-packages/django/forms/forms.py", line 437, in full_clean
    self._clean_fields()
  File "/home/ed/PycharmProjects/wikidataDiscovery/wd_venv/lib/python3.10/site-packages/django/forms/forms.py", line 444, in _clean_fields
    value = bf.initial if field.disabled else bf.data
  File "/home/ed/PycharmProjects/wikidataDiscovery/wd_venv/lib/python3.10/site-packages/django/forms/boundfield.py", line 127, in data
    return self.form._widget_data_value(self.field.widget, self.html_name)
  File "/home/ed/PycharmProjects/wikidataDiscovery/wd_venv/lib/python3.10/site-packages/django/forms/forms.py", line 224, in _widget_data_value
    return widget.value_from_datadict(self.data, self.files, html_name)
  File "/home/ed/PycharmProjects/wikidataDiscovery/wd_venv/lib/python3.10/site-packages/django/forms/widgets.py", line 297, in value_from_datadict
    return data.get(name)
AttributeError: 'WSGIRequest' object has no attribute 'get'
"POST /discover/testy_processed/ HTTP/1.1" 500 105585
Internal Server Error: /discover/testy_processed/
Traceback (most recent call last):
  File "/home/ed/PycharmProjects/wikidataDiscovery/wd_venv/lib/python3.10/site-packages/django/core/handlers/exception.py", line 56, in inner
    response = get_response(request)
  File "/home/ed/PycharmProjects/wikidataDiscovery/wd_venv/lib/python3.10/site-packages/django/core/handlers/base.py", line 197, in _get_response
    response = wrapped_callback(request, *callback_args, **callback_kwargs)
  File "/home/ed/PycharmProjects/wikidataDiscovery/discover/views.py", line 32, in testy_processed
    if lf.is_valid():
  File "/home/ed/PycharmProjects/wikidataDiscovery/wd_venv/lib/python3.10/site-packages/django/forms/forms.py", line 205, in is_valid
    return self.is_bound and not self.errors
  File "/home/ed/PycharmProjects/wikidataDiscovery/wd_venv/lib/python3.10/site-packages/django/forms/forms.py", line 200, in errors
    self.full_clean()
  File "/home/ed/PycharmProjects/wikidataDiscovery/wd_venv/lib/python3.10/site-packages/django/forms/forms.py", line 437, in full_clean
    self._clean_fields()
  File "/home/ed/PycharmProjects/wikidataDiscovery/wd_venv/lib/python3.10/site-packages/django/forms/forms.py", line 444, in _clean_fields
    value = bf.initial if field.disabled else bf.data
  File "/home/ed/PycharmProjects/wikidataDiscovery/wd_venv/lib/python3.10/site-packages/django/forms/boundfield.py", line 127, in data
    return self.form._widget_data_value(self.field.widget, self.html_name)
  File "/home/ed/PycharmProjects/wikidataDiscovery/wd_venv/lib/python3.10/site-packages/django/forms/forms.py", line 224, in _widget_data_value
    return widget.value_from_datadict(self.data, self.files, html_name)
  File "/home/ed/PycharmProjects/wikidataDiscovery/wd_venv/lib/python3.10/site-packages/django/forms/widgets.py", line 297, in value_from_datadict
    return data.get(name)
AttributeError: 'WSGIRequest' object has no attribute 'get'
"POST /discover/testy_processed/ HTTP/1.1" 500 105585
Internal Server Error: /discover/testy_processed/
Traceback (most recent call last):
  File "/usr/local/lib/python3.10/dist-packages/django/core/handlers/exception.py", line 56, in inner
    response = get_response(request)
  File "/usr/local/lib/python3.10/dist-packages/django/core/handlers/base.py", line 197, in _get_response
    response = wrapped_callback(request, *callback_args, **callback_kwargs)
  File "/home/ed/PycharmProjects/wikidataDiscovery/discover/views.py", line 32, in testy_processed
    if lf.is_valid():
  File "/usr/local/lib/python3.10/dist-packages/django/forms/forms.py", line 205, in is_valid
    return self.is_bound and not self.errors
  File "/usr/local/lib/python3.10/dist-packages/django/forms/forms.py", line 200, in errors
    self.full_clean()
  File "/usr/local/lib/python3.10/dist-packages/django/forms/forms.py", line 437, in full_clean
    self._clean_fields()
  File "/usr/local/lib/python3.10/dist-packages/django/forms/forms.py", line 444, in _clean_fields
    value = bf.initial if field.disabled else bf.data
  File "/usr/local/lib/python3.10/dist-packages/django/forms/boundfield.py", line 127, in data
    return self.form._widget_data_value(self.field.widget, self.html_name)
  File "/usr/local/lib/python3.10/dist-packages/django/forms/forms.py", line 224, in _widget_data_value
    return widget.value_from_datadict(self.data, self.files, html_name)
  File "/usr/local/lib/python3.10/dist-packages/django/forms/widgets.py", line 297, in value_from_datadict
    return data.get(name)
AttributeError: 'WSGIRequest' object has no attribute 'get'
"POST /discover/testy_processed/ HTTP/1.1" 500 104591
Internal Server Error: /discover/testy_processed/
Traceback (most recent call last):
  File "/usr/local/lib/python3.10/dist-packages/django/core/handlers/exception.py", line 56, in inner
    response = get_response(request)
  File "/usr/local/lib/python3.10/dist-packages/django/core/handlers/base.py", line 197, in _get_response
    response = wrapped_callback(request, *callback_args, **callback_kwargs)
  File "/home/ed/PycharmProjects/wikidataDiscovery/discover/views.py", line 32, in testy_processed
    if lf.is_valid():
  File "/usr/local/lib/python3.10/dist-packages/django/forms/forms.py", line 205, in is_valid
    return self.is_bound and not self.errors
  File "/usr/local/lib/python3.10/dist-packages/django/forms/forms.py", line 200, in errors
    self.full_clean()
  File "/usr/local/lib/python3.10/dist-packages/django/forms/forms.py", line 437, in full_clean
    self._clean_fields()
  File "/usr/local/lib/python3.10/dist-packages/django/forms/forms.py", line 444, in _clean_fields
    value = bf.initial if field.disabled else bf.data
  File "/usr/local/lib/python3.10/dist-packages/django/forms/boundfield.py", line 127, in data
    return self.form._widget_data_value(self.field.widget, self.html_name)
  File "/usr/local/lib/python3.10/dist-packages/django/forms/forms.py", line 224, in _widget_data_value
    return widget.value_from_datadict(self.data, self.files, html_name)
  File "/usr/local/lib/python3.10/dist-packages/django/forms/widgets.py", line 297, in value_from_datadict
    return data.get(name)
AttributeError: 'WSGIRequest' object has no attribute 'get'
"POST /discover/testy_processed/ HTTP/1.1" 500 104587
Internal Server Error: /discover/testy_processed/
Traceback (most recent call last):
  File "/usr/local/lib/python3.10/dist-packages/django/core/handlers/exception.py", line 56, in inner
    response = get_response(request)
  File "/usr/local/lib/python3.10/dist-packages/django/core/handlers/base.py", line 197, in _get_response
    response = wrapped_callback(request, *callback_args, **callback_kwargs)
  File "/home/ed/PycharmProjects/wikidataDiscovery/discover/views.py", line 32, in testy_processed
    if lf.is_valid():
  File "/usr/local/lib/python3.10/dist-packages/django/forms/forms.py", line 205, in is_valid
    return self.is_bound and not self.errors
  File "/usr/local/lib/python3.10/dist-packages/django/forms/forms.py", line 200, in errors
    self.full_clean()
  File "/usr/local/lib/python3.10/dist-packages/django/forms/forms.py", line 437, in full_clean
    self._clean_fields()
  File "/usr/local/lib/python3.10/dist-packages/django/forms/forms.py", line 444, in _clean_fields
    value = bf.initial if field.disabled else bf.data
  File "/usr/local/lib/python3.10/dist-packages/django/forms/boundfield.py", line 127, in data
    return self.form._widget_data_value(self.field.widget, self.html_name)
  File "/usr/local/lib/python3.10/dist-packages/django/forms/forms.py", line 224, in _widget_data_value
    return widget.value_from_datadict(self.data, self.files, html_name)
  File "/usr/local/lib/python3.10/dist-packages/django/forms/widgets.py", line 297, in value_from_datadict
    return data.get(name)
AttributeError: 'WSGIRequest' object has no attribute 'get'
"POST /discover/testy_processed/ HTTP/1.1" 500 104589
Internal Server Error: /discover/testy_processed/
Traceback (most recent call last):
  File "/usr/local/lib/python3.10/dist-packages/django/forms/forms.py", line 182, in __getitem__
    field = self.fields[name]
KeyError: 'csrfmiddlewaretoken'

During handling of the above exception, another exception occurred:

Traceback (most recent call last):
  File "/usr/local/lib/python3.10/dist-packages/django/core/handlers/exception.py", line 56, in inner
    response = get_response(request)
  File "/usr/local/lib/python3.10/dist-packages/django/core/handlers/base.py", line 197, in _get_response
    response = wrapped_callback(request, *callback_args, **callback_kwargs)
  File "/home/ed/PycharmProjects/wikidataDiscovery/discover/views.py", line 31, in testy_processed
    print(lf['csrfmiddlewaretoken'])
  File "/usr/local/lib/python3.10/dist-packages/django/forms/forms.py", line 184, in __getitem__
    raise KeyError(
KeyError: "Key 'csrfmiddlewaretoken' not found in 'LittleForm'. Choices are: the_data."
"POST /discover/testy_processed/ HTTP/1.1" 500 85370
Internal Server Error: /discover/testy_processed/
Traceback (most recent call last):
  File "/usr/local/lib/python3.10/dist-packages/django/forms/forms.py", line 182, in __getitem__
    field = self.fields[name]
KeyError: 'csrfmiddlewaretoken'

During handling of the above exception, another exception occurred:

Traceback (most recent call last):
  File "/usr/local/lib/python3.10/dist-packages/django/core/handlers/exception.py", line 56, in inner
    response = get_response(request)
  File "/usr/local/lib/python3.10/dist-packages/django/core/handlers/base.py", line 197, in _get_response
    response = wrapped_callback(request, *callback_args, **callback_kwargs)
  File "/home/ed/PycharmProjects/wikidataDiscovery/discover/views.py", line 31, in testy_processed
    print(lf['csrfmiddlewaretoken'])
  File "/usr/local/lib/python3.10/dist-packages/django/forms/forms.py", line 184, in __getitem__
    raise KeyError(
KeyError: "Key 'csrfmiddlewaretoken' not found in 'LittleForm'. Choices are: the_data."
"POST /discover/testy_processed/ HTTP/1.1" 500 85370
Internal Server Error: /discover/testy_processed/
Traceback (most recent call last):
  File "/usr/local/lib/python3.10/dist-packages/django/core/handlers/exception.py", line 56, in inner
    response = get_response(request)
  File "/usr/local/lib/python3.10/dist-packages/django/core/handlers/base.py", line 197, in _get_response
    response = wrapped_callback(request, *callback_args, **callback_kwargs)
  File "/home/ed/PycharmProjects/wikidataDiscovery/discover/views.py", line 31, in testy_processed
    queue_mgr.update_queue(lf, request.session.session_key)
  File "/home/ed/PycharmProjects/wikidataDiscovery/discover/queue_mgr.py", line 18, in update_queue
    form_choices = form.cleaned_data['the_choices'].join(';')
AttributeError: 'list' object has no attribute 'join'
"POST /discover/testy_processed/ HTTP/1.1" 500 82597
Internal Server Error: /discover/testy_processed/
Traceback (most recent call last):
  File "/usr/local/lib/python3.10/dist-packages/django/core/handlers/exception.py", line 56, in inner
    response = get_response(request)
  File "/usr/local/lib/python3.10/dist-packages/django/core/handlers/base.py", line 197, in _get_response
    response = wrapped_callback(request, *callback_args, **callback_kwargs)
  File "/home/ed/PycharmProjects/wikidataDiscovery/discover/views.py", line 31, in testy_processed
    queue_mgr.update_queue(lf, request.session.session_key)
  File "/home/ed/PycharmProjects/wikidataDiscovery/discover/queue_mgr.py", line 18, in update_queue
    form_choices = form.cleaned_data['the_choices'].split()
AttributeError: 'list' object has no attribute 'split'
"POST /discover/testy_processed/ HTTP/1.1" 500 82577
Internal Server Error: /discover/testy_processed/
Traceback (most recent call last):
  File "/usr/local/lib/python3.10/dist-packages/django/core/handlers/exception.py", line 56, in inner
    response = get_response(request)
  File "/usr/local/lib/python3.10/dist-packages/django/core/handlers/base.py", line 197, in _get_response
    response = wrapped_callback(request, *callback_args, **callback_kwargs)
  File "/home/ed/PycharmProjects/wikidataDiscovery/discover/views.py", line 31, in testy_processed
    queue_mgr.update_queue(lf, request.session.session_key)
  File "/home/ed/PycharmProjects/wikidataDiscovery/discover/queue_mgr.py", line 19, in update_queue
    sess['top']['form_type'] = form_type
  File "/usr/local/lib/python3.10/dist-packages/django/contrib/sessions/backends/base.py", line 53, in __getitem__
    return self._session[key]
KeyError: 'top'
"POST /discover/testy_processed/ HTTP/1.1" 500 86243
Internal Server Error: /discover/testy_processed/
Traceback (most recent call last):
  File "/usr/local/lib/python3.10/dist-packages/django/core/handlers/exception.py", line 56, in inner
    response = get_response(request)
  File "/usr/local/lib/python3.10/dist-packages/django/core/handlers/base.py", line 197, in _get_response
    response = wrapped_callback(request, *callback_args, **callback_kwargs)
  File "/home/ed/PycharmProjects/wikidataDiscovery/discover/views.py", line 31, in testy_processed
    queue_mgr.update_queue(lf, request.session.session_key)
  File "/home/ed/PycharmProjects/wikidataDiscovery/discover/queue_mgr.py", line 23, in update_queue
    sess['top']['form_type'] = form_type
  File "/usr/local/lib/python3.10/dist-packages/django/contrib/sessions/backends/base.py", line 53, in __getitem__
    return self._session[key]
KeyError: 'top'
"POST /discover/testy_processed/ HTTP/1.1" 500 86216
Internal Server Error: /discover/testy_processed/
Traceback (most recent call last):
  File "/usr/local/lib/python3.10/dist-packages/django/core/handlers/exception.py", line 56, in inner
    response = get_response(request)
  File "/usr/local/lib/python3.10/dist-packages/django/core/handlers/base.py", line 197, in _get_response
    response = wrapped_callback(request, *callback_args, **callback_kwargs)
  File "/home/ed/PycharmProjects/wikidataDiscovery/discover/views.py", line 28, in testy_processed
    if not request.session.session_key():
TypeError: 'NoneType' object is not callable
"POST /discover/testy_processed/ HTTP/1.1" 500 77136
Internal Server Error: /discover/testy_processed/
Traceback (most recent call last):
  File "/usr/local/lib/python3.10/dist-packages/django/core/handlers/exception.py", line 56, in inner
    response = get_response(request)
  File "/usr/local/lib/python3.10/dist-packages/django/core/handlers/base.py", line 197, in _get_response
    response = wrapped_callback(request, *callback_args, **callback_kwargs)
  File "/home/ed/PycharmProjects/wikidataDiscovery/discover/views.py", line 38, in testy_processed
    queue_mgr.update_queue(lf, request.session.session_key)
  File "/home/ed/PycharmProjects/wikidataDiscovery/discover/queue_mgr.py", line 19, in update_queue
    if sess['middle']:
  File "/usr/local/lib/python3.10/dist-packages/django/contrib/sessions/backends/base.py", line 53, in __getitem__
    return self._session[key]
KeyError: 'middle'
"POST /discover/testy_processed/ HTTP/1.1" 500 85722
Internal Server Error: /discover/testy_processed/
Traceback (most recent call last):
  File "/usr/local/lib/python3.10/dist-packages/django/core/handlers/exception.py", line 56, in inner
    response = get_response(request)
  File "/usr/local/lib/python3.10/dist-packages/django/core/handlers/base.py", line 197, in _get_response
    response = wrapped_callback(request, *callback_args, **callback_kwargs)
  File "/home/ed/PycharmProjects/wikidataDiscovery/discover/views.py", line 41, in testy_processed
    queue_mgr.update_queue(lf, request.session.session_key)
  File "/home/ed/PycharmProjects/wikidataDiscovery/discover/queue_mgr.py", line 19, in update_queue
    sess['bottom'] = sess['middle']
  File "/usr/local/lib/python3.10/dist-packages/django/contrib/sessions/backends/base.py", line 53, in __getitem__
    return self._session[key]
KeyError: 'middle'
"POST /discover/testy_processed/ HTTP/1.1" 500 85535
Internal Server Error: /discover/testy_processed/
Traceback (most recent call last):
  File "/usr/local/lib/python3.10/dist-packages/django/core/handlers/exception.py", line 56, in inner
    response = get_response(request)
  File "/usr/local/lib/python3.10/dist-packages/django/core/handlers/base.py", line 197, in _get_response
    response = wrapped_callback(request, *callback_args, **callback_kwargs)
  File "/home/ed/PycharmProjects/wikidataDiscovery/discover/views.py", line 41, in testy_processed
    queue_mgr.update_queue(lf, request.session.session_key)
  File "/home/ed/PycharmProjects/wikidataDiscovery/discover/queue_mgr.py", line 19, in update_queue
    sess['bottom'] = sess['middle']
  File "/usr/local/lib/python3.10/dist-packages/django/contrib/sessions/backends/base.py", line 53, in __getitem__
    return self._session[key]
KeyError: 'middle'
"POST /discover/testy_processed/ HTTP/1.1" 500 85535
Internal Server Error: /discover/testy_processed/
Traceback (most recent call last):
  File "/usr/local/lib/python3.10/dist-packages/django/core/handlers/exception.py", line 56, in inner
    response = get_response(request)
  File "/usr/local/lib/python3.10/dist-packages/django/core/handlers/base.py", line 197, in _get_response
    response = wrapped_callback(request, *callback_args, **callback_kwargs)
  File "/home/ed/PycharmProjects/wikidataDiscovery/discover/views.py", line 40, in testy_processed
    print(request.session['test_it'])
  File "/usr/local/lib/python3.10/dist-packages/django/contrib/sessions/backends/base.py", line 53, in __getitem__
    return self._session[key]
KeyError: 'test_it'
"POST /discover/testy_processed/ HTTP/1.1" 500 81408
Internal Server Error: /discover/testy_processed/
Traceback (most recent call last):
  File "/usr/local/lib/python3.10/dist-packages/django/core/handlers/exception.py", line 56, in inner
    response = get_response(request)
  File "/usr/local/lib/python3.10/dist-packages/django/core/handlers/base.py", line 197, in _get_response
    response = wrapped_callback(request, *callback_args, **callback_kwargs)
  File "/home/ed/PycharmProjects/wikidataDiscovery/discover/views.py", line 41, in testy_processed
    queue_mgr.update_queue(lf, request.session.session_key)
  File "/home/ed/PycharmProjects/wikidataDiscovery/discover/queue_mgr.py", line 19, in update_queue
    sess['bottom'] = sess['middle']
  File "/usr/local/lib/python3.10/dist-packages/django/contrib/sessions/backends/base.py", line 53, in __getitem__
    return self._session[key]
KeyError: 'middle'
"POST /discover/testy_processed/ HTTP/1.1" 500 85535
Internal Server Error: /discover/testy_processed/
Traceback (most recent call last):
  File "/usr/local/lib/python3.10/dist-packages/django/core/handlers/exception.py", line 56, in inner
    response = get_response(request)
  File "/usr/local/lib/python3.10/dist-packages/django/core/handlers/base.py", line 197, in _get_response
    response = wrapped_callback(request, *callback_args, **callback_kwargs)
  File "/home/ed/PycharmProjects/wikidataDiscovery/discover/views.py", line 35, in testy_processed
    curr_request = queue_mgr.create_request(request.session_key, 'middle')
AttributeError: 'WSGIRequest' object has no attribute 'session_key'
"POST /discover/testy_processed/ HTTP/1.1" 500 77753
Internal Server Error: /discover/testy_processed/
Traceback (most recent call last):
  File "/usr/local/lib/python3.10/dist-packages/django/core/handlers/exception.py", line 56, in inner
    response = get_response(request)
  File "/usr/local/lib/python3.10/dist-packages/django/core/handlers/base.py", line 197, in _get_response
    response = wrapped_callback(request, *callback_args, **callback_kwargs)
  File "/home/ed/PycharmProjects/wikidataDiscovery/discover/views.py", line 40, in testy_processed
    queue_mgr.update_queue(lf, curr_request.session.session_key)
AttributeError: 'WSGIRequest' object has no attribute 'session'
"POST /discover/testy_processed/ HTTP/1.1" 500 78445
Internal Server Error: /discover/testy/
Traceback (most recent call last):
  File "/usr/local/lib/python3.10/dist-packages/django/core/handlers/exception.py", line 56, in inner
    response = get_response(request)
  File "/usr/local/lib/python3.10/dist-packages/django/core/handlers/base.py", line 197, in _get_response
    response = wrapped_callback(request, *callback_args, **callback_kwargs)
  File "/home/ed/PycharmProjects/wikidataDiscovery/discover/views.py", line 19, in testy
    queue_mgr.set_queue_list(request.session.session_key))
  File "/home/ed/PycharmProjects/wikidataDiscovery/discover/queue_mgr.py", line 97, in set_queue_list
    ('top', sess['top']['form_vals'][top_search_key][:100]),
KeyError: '2nd test'
"GET /discover/testy/ HTTP/1.1" 500 80354
Internal Server Error: /discover/testy/
Traceback (most recent call last):
  File "/usr/local/lib/python3.10/dist-packages/django/core/handlers/exception.py", line 56, in inner
    response = get_response(request)
  File "/usr/local/lib/python3.10/dist-packages/django/core/handlers/base.py", line 197, in _get_response
    response = wrapped_callback(request, *callback_args, **callback_kwargs)
  File "/home/ed/PycharmProjects/wikidataDiscovery/discover/views.py", line 19, in testy
    queue_mgr.set_queue_list(request.session.session_key))
  File "/home/ed/PycharmProjects/wikidataDiscovery/discover/queue_mgr.py", line 72, in set_queue_list
    if sess['top']['form_type'] == 'little':
TypeError: string indices must be integers
"GET /discover/testy/ HTTP/1.1" 500 79700
Internal Server Error: /discover/testy/
Traceback (most recent call last):
  File "/usr/local/lib/python3.10/dist-packages/django/core/handlers/exception.py", line 56, in inner
    response = get_response(request)
  File "/usr/local/lib/python3.10/dist-packages/django/core/handlers/base.py", line 197, in _get_response
    response = wrapped_callback(request, *callback_args, **callback_kwargs)
  File "/home/ed/PycharmProjects/wikidataDiscovery/discover/views.py", line 19, in testy
    queue_mgr.set_queue_list(request.session.session_key))
  File "/home/ed/PycharmProjects/wikidataDiscovery/discover/queue_mgr.py", line 108, in set_queue_list
    ('bottom', sess['bottom']['form_vals'][bottom_search_key][:50] + '...')]
KeyError: 'the data'
"GET /discover/testy/ HTTP/1.1" 500 79683
Internal Server Error: /discover/testy_processed/
Traceback (most recent call last):
  File "/usr/local/lib/python3.10/dist-packages/django/core/handlers/exception.py", line 56, in inner
    response = get_response(request)
  File "/usr/local/lib/python3.10/dist-packages/django/core/handlers/base.py", line 197, in _get_response
    response = wrapped_callback(request, *callback_args, **callback_kwargs)
  File "/home/ed/PycharmProjects/wikidataDiscovery/discover/views.py", line 47, in testy_processed
    queue_mgr.update_queue(lf, request.session.session_key)
TypeError: update_queue() missing 1 required positional argument: 'session_key'
"POST /discover/testy_processed/ HTTP/1.1" 500 78544
2023-06-09 14:28:52.187103: ("'QuerySet' object has no attribute 'relation_type'",)'QuerySet' object has no attribute 'relation_type' search_processed
2023-06-09 14:39:16.254191: ('choices',)choices search_processed
2023-06-09 14:41:45.780855: ('discover/people_filtered.html',)discover/people_filtered.html search_processed
2023-06-10 02:58:14.561608: ('search_text',)search_text search_processed
2023-06-10 03:10:11.778656: ('search_text',)search_text views.search_processed
2023-06-10 03:20:57.365147: ('search_text',)search_text views.search_processed
2023-06-10 04:16:26.852239: ('search_text',)search_text views.search_processed
2023-06-10 04:17:05.479428: ('search_text',)search_text views.search_processed
2023-06-10 04:17:17.777391: ('search_text',)search_text views.search_processed
2023-06-10 04:17:53.297866: ('search_text',)search_text views.search_processed
2023-06-10 04:35:59.461219: ('search_text',)search_text views.search_processed
2023-06-10 05:20:15.756305: ("local variable 'results' referenced before assignment",)local variable 'results' referenced before assignment views.search_processed
2023-06-10 05:37:52.302706: You've used an invalid search string. Try again.1064 views.search_processed
2023-06-10 06:18:19.776573: You've used an invalid search string. Try again.1064 views.search_processed
2023-06-10 07:55:55.372526: You've used an invalid search string. Try again.1064 views.search_processed
2023-06-10 09:30:15.214685: ("local variable 'results' referenced before assignment",)local variable 'results' referenced before assignment views.search_processed
2023-06-10 09:30:28.201958: ("local variable 'results' referenced before assignment",)local variable 'results' referenced before assignment views.search_processed
Internal Server Error: /discover/people_filtered/
Traceback (most recent call last):
  File "/home/ed/PycharmProjects/wikidataDiscovery/discover/views.py", line 135, in search_processed
    return render(request, 'discover/base_people_filtered.html', context)
UnboundLocalError: local variable 'context' referenced before assignment

During handling of the above exception, another exception occurred:

Traceback (most recent call last):
  File "/usr/local/lib/python3.10/dist-packages/django/core/handlers/exception.py", line 56, in inner
    response = get_response(request)
  File "/usr/local/lib/python3.10/dist-packages/django/core/handlers/base.py", line 197, in _get_response
    response = wrapped_callback(request, *callback_args, **callback_kwargs)
  File "/home/ed/PycharmProjects/wikidataDiscovery/discover/views.py", line 151, in search_processed
    return render(request, final_path, context)
UnboundLocalError: local variable 'context' referenced before assignment
"POST /discover/people_filtered/ HTTP/1.1" 500 109572
Internal Server Error: /discover/people_filtered/
Traceback (most recent call last):
  File "/home/ed/PycharmProjects/wikidataDiscovery/discover/views.py", line 149, in search_processed
    context = {'domain': curr_facet, 'unique_list': results['unique'], 'search': sform, 'priors': qform,
UnboundLocalError: local variable 'results' referenced before assignment

During handling of the above exception, another exception occurred:

Traceback (most recent call last):
  File "/usr/local/lib/python3.10/dist-packages/django/core/handlers/exception.py", line 56, in inner
    response = get_response(request)
  File "/usr/local/lib/python3.10/dist-packages/django/core/handlers/base.py", line 197, in _get_response
    response = wrapped_callback(request, *callback_args, **callback_kwargs)
  File "/home/ed/PycharmProjects/wikidataDiscovery/discover/views.py", line 154, in search_processed
    return render(request, final_path, context)
UnboundLocalError: local variable 'context' referenced before assignment
"POST /discover/people_filtered/ HTTP/1.1" 500 93066
Internal Server Error: /discover/people_filtered/
Traceback (most recent call last):
  File "/home/ed/PycharmProjects/wikidataDiscovery/discover/views.py", line 149, in search_processed
    context = {'domain': curr_facet, 'unique_list': results['unique'], 'search': sform, 'priors': qform,
UnboundLocalError: local variable 'results' referenced before assignment

During handling of the above exception, another exception occurred:

Traceback (most recent call last):
  File "/usr/local/lib/python3.10/dist-packages/django/core/handlers/exception.py", line 56, in inner
    response = get_response(request)
  File "/usr/local/lib/python3.10/dist-packages/django/core/handlers/base.py", line 197, in _get_response
    response = wrapped_callback(request, *callback_args, **callback_kwargs)
  File "/home/ed/PycharmProjects/wikidataDiscovery/discover/views.py", line 154, in search_processed
    return render(request, final_path, context)
UnboundLocalError: local variable 'context' referenced before assignment
"POST /discover/people_filtered/ HTTP/1.1" 500 93066
Internal Server Error: /discover/people_filtered/
Traceback (most recent call last):
  File "/home/ed/PycharmProjects/wikidataDiscovery/discover/views.py", line 150, in search_processed
    context = {'domain': curr_facet, 'unique_list': results['unique'], 'search': sform, 'priors': qform,
UnboundLocalError: local variable 'results' referenced before assignment

During handling of the above exception, another exception occurred:

Traceback (most recent call last):
  File "/usr/local/lib/python3.10/dist-packages/django/core/handlers/exception.py", line 56, in inner
    response = get_response(request)
  File "/usr/local/lib/python3.10/dist-packages/django/core/handlers/base.py", line 197, in _get_response
    response = wrapped_callback(request, *callback_args, **callback_kwargs)
  File "/home/ed/PycharmProjects/wikidataDiscovery/discover/views.py", line 155, in search_processed
    return render(request, final_path, context)
UnboundLocalError: local variable 'context' referenced before assignment
"POST /discover/people_filtered/ HTTP/1.1" 500 93066
Internal Server Error: /discover/people_filtered/
Traceback (most recent call last):
  File "/home/ed/PycharmProjects/wikidataDiscovery/discover/views.py", line 150, in search_processed
    context = {'domain': curr_facet, 'unique_list': results['unique'], 'search': sform, 'priors': qform,
UnboundLocalError: local variable 'results' referenced before assignment

During handling of the above exception, another exception occurred:

Traceback (most recent call last):
  File "/usr/local/lib/python3.10/dist-packages/django/core/handlers/exception.py", line 56, in inner
    response = get_response(request)
  File "/usr/local/lib/python3.10/dist-packages/django/core/handlers/base.py", line 197, in _get_response
    response = wrapped_callback(request, *callback_args, **callback_kwargs)
  File "/home/ed/PycharmProjects/wikidataDiscovery/discover/views.py", line 155, in search_processed
    return render(request, final_path, context)
UnboundLocalError: local variable 'context' referenced before assignment
"POST /discover/people_filtered/ HTTP/1.1" 500 93066
2023-06-10 10:29:06.338948: ("local variable 'results' referenced before assignment",)local variable 'results' referenced before assignment views.search_processed
2023-06-10 10:29:34.043908: ("local variable 'results' referenced before assignment",)local variable 'results' referenced before assignment views.search_processed
2023-06-10 10:38:27.415019: ("local variable 'results' referenced before assignment",)local variable 'results' referenced before assignment views.search_processed
2023-06-10 10:39:50.248121: ("local variable 'results' referenced before assignment",)local variable 'results' referenced before assignment views.search_processed
2023-06-10 10:40:17.065855: ("local variable 'results' referenced before assignment",)local variable 'results' referenced before assignment views.search_processed
2023-06-10 10:40:40.024108: ("local variable 'results' referenced before assignment",)local variable 'results' referenced before assignment views.search_processed
2023-06-10 10:41:19.678355: ("local variable 'results' referenced before assignment",)local variable 'results' referenced before assignment views.search_processed
2023-06-10 10:43:44.036560: ("local variable 'results' referenced before assignment",)local variable 'results' referenced before assignment views.search_processed
2023-06-10 10:46:15.815950: ("local variable 'results' referenced before assignment",)local variable 'results' referenced before assignment views.search_processed
2023-06-10 10:56:13.209255: You've used an invalid search string. Try again.1064 views.search_processed
2023-06-10 10:57:48.834836: You've used an invalid search string. Try again.1064 views.search_processed
2023-06-10 10:58:03.340182: You've used an invalid search string. Try again.1064 views.search_processed
2023-06-10 10:58:26.565855: You've used an invalid search string. Try again.1064 views.search_processed
2023-06-10 10:58:34.498846: You've used an invalid search string. Try again.1064 views.search_processed
2023-06-10 10:59:12.109464: You've used an invalid search string. Try again.1064 views.search_processed
2023-06-10 11:07:02.566239: You've used an invalid search string. Try again.1064 views.search_processed
2023-06-10 11:07:54.704305: You've used an invalid search string. Try again.1064 views.search_processed
2023-06-10 11:07:59.610041: You've used an invalid search string. Try again.1064 views.search_processed
2023-06-10 11:13:05.186295: You've used an invalid search string. Try again.1064 views.search_processed
2023-06-10 11:20:03.565613: You've used an invalid search string. Try again.1064 views.search_processed
2023-06-11 08:19:41.454662: ('string indices must be integers',)string indices must be integers views.search_processed
Internal Server Error: /discover/people/
Traceback (most recent call last):
  File "/home/ed/PycharmProjects/wikidataDiscovery/wd_venv/lib/python3.10/site-packages/django/core/handlers/exception.py", line 56, in inner
    response = get_response(request)
  File "/home/ed/PycharmProjects/wikidataDiscovery/wd_venv/lib/python3.10/site-packages/django/core/handlers/base.py", line 197, in _get_response
    response = wrapped_callback(request, *callback_args, **callback_kwargs)
  File "/home/ed/PycharmProjects/wikidataDiscovery/discover/views.py", line 68, in people
    dynamic_choices=queue_mgr.get_queue_list(request.session.session_key))
  File "/home/ed/PycharmProjects/wikidataDiscovery/discover/queue_mgr.py", line 132, in get_queue_list
    if sess['top']['form_type']['nodel_label'] == '':
TypeError: string indices must be integers
"GET /discover/people/ HTTP/1.1" 500 81716
Internal Server Error: /discover/people/
Traceback (most recent call last):
  File "/home/ed/PycharmProjects/wikidataDiscovery/wd_venv/lib/python3.10/site-packages/django/core/handlers/exception.py", line 56, in inner
    response = get_response(request)
  File "/home/ed/PycharmProjects/wikidataDiscovery/wd_venv/lib/python3.10/site-packages/django/core/handlers/base.py", line 197, in _get_response
    response = wrapped_callback(request, *callback_args, **callback_kwargs)
  File "/home/ed/PycharmProjects/wikidataDiscovery/discover/views.py", line 68, in people
    dynamic_choices=queue_mgr.get_queue_list(request.session.session_key))
  File "/home/ed/PycharmProjects/wikidataDiscovery/discover/queue_mgr.py", line 132, in get_queue_list
    if sess['top']['form_type']['node_label'] == '':
TypeError: string indices must be integers
"GET /discover/people/ HTTP/1.1" 500 81698
Internal Server Error: /discover/people/
Traceback (most recent call last):
  File "/home/ed/PycharmProjects/wikidataDiscovery/wd_venv/lib/python3.10/site-packages/django/core/handlers/exception.py", line 56, in inner
    response = get_response(request)
  File "/home/ed/PycharmProjects/wikidataDiscovery/wd_venv/lib/python3.10/site-packages/django/core/handlers/base.py", line 197, in _get_response
    response = wrapped_callback(request, *callback_args, **callback_kwargs)
  File "/home/ed/PycharmProjects/wikidataDiscovery/discover/views.py", line 68, in people
    dynamic_choices=queue_mgr.get_queue_list(request.session.session_key))
  File "/home/ed/PycharmProjects/wikidataDiscovery/discover/queue_mgr.py", line 133, in get_queue_list
    if sess['top']['form_vals']['prior_node_label'] == '':
KeyError: 'prior_node_label'
"GET /discover/people/ HTTP/1.1" 500 81712
2023-06-11 08:46:01.561447: ('prior_search',)prior_search views.search_processed
Internal Server Error: /discover/people/
Traceback (most recent call last):
  File "/home/ed/PycharmProjects/wikidataDiscovery/wd_venv/lib/python3.10/site-packages/django/core/handlers/exception.py", line 56, in inner
    response = get_response(request)
  File "/home/ed/PycharmProjects/wikidataDiscovery/wd_venv/lib/python3.10/site-packages/django/core/handlers/base.py", line 197, in _get_response
    response = wrapped_callback(request, *callback_args, **callback_kwargs)
  File "/home/ed/PycharmProjects/wikidataDiscovery/discover/views.py", line 68, in people
    dynamic_choices=queue_mgr.get_queue_list(request.session.session_key))
  File "/home/ed/PycharmProjects/wikidataDiscovery/discover/queue_mgr.py", line 205, in get_queue_list
    sess['middle']['form_vals'][mid_search_key][:50] + '...' + mid_rel_types))
KeyError: 'prior_search'
"GET /discover/people/ HTTP/1.1" 500 83371
Internal Server Error: /discover/people/
Traceback (most recent call last):
  File "/home/ed/PycharmProjects/wikidataDiscovery/wd_venv/lib/python3.10/site-packages/django/core/handlers/exception.py", line 56, in inner
    response = get_response(request)
  File "/home/ed/PycharmProjects/wikidataDiscovery/wd_venv/lib/python3.10/site-packages/django/core/handlers/base.py", line 197, in _get_response
    response = wrapped_callback(request, *callback_args, **callback_kwargs)
  File "/home/ed/PycharmProjects/wikidataDiscovery/discover/views.py", line 68, in people
    dynamic_choices=queue_mgr.get_queue_list(request.session.session_key))
  File "/home/ed/PycharmProjects/wikidataDiscovery/discover/queue_mgr.py", line 205, in get_queue_list
    sess['middle']['form_vals'][mid_search_key][:50] + '...' + mid_rel_types))
KeyError: 'prior_search'
"GET /discover/people/ HTTP/1.1" 500 83355
Internal Server Error: /discover/people/
Traceback (most recent call last):
  File "/home/ed/PycharmProjects/wikidataDiscovery/wd_venv/lib/python3.10/site-packages/django/core/handlers/exception.py", line 56, in inner
    response = get_response(request)
  File "/home/ed/PycharmProjects/wikidataDiscovery/wd_venv/lib/python3.10/site-packages/django/core/handlers/base.py", line 197, in _get_response
    response = wrapped_callback(request, *callback_args, **callback_kwargs)
  File "/home/ed/PycharmProjects/wikidataDiscovery/discover/views.py", line 68, in people
    dynamic_choices=queue_mgr.get_queue_list(request.session.session_key))
  File "/home/ed/PycharmProjects/wikidataDiscovery/discover/queue_mgr.py", line 205, in get_queue_list
    sess['middle']['form_vals'][mid_search_key][:50] + '...' + mid_rel_types))
KeyError: 'prior_search'
"GET /discover/people/ HTTP/1.1" 500 83355
2023-06-11 09:06:52.619587: You've used an invalid search string. Try again.1064 views.search_processed
2023-06-11 09:07:26.352111: ('prior_search',)prior_search views.search_processed
Internal Server Error: /discover/people/
Traceback (most recent call last):
  File "/home/ed/PycharmProjects/wikidataDiscovery/wd_venv/lib/python3.10/site-packages/django/core/handlers/exception.py", line 56, in inner
    response = get_response(request)
  File "/home/ed/PycharmProjects/wikidataDiscovery/wd_venv/lib/python3.10/site-packages/django/core/handlers/base.py", line 197, in _get_response
    response = wrapped_callback(request, *callback_args, **callback_kwargs)
  File "/home/ed/PycharmProjects/wikidataDiscovery/discover/views.py", line 68, in people
    dynamic_choices=queue_mgr.get_queue_list(request.session.session_key))
  File "/home/ed/PycharmProjects/wikidataDiscovery/discover/queue_mgr.py", line 205, in get_queue_list
    sess['middle']['form_vals'][mid_search_key][:50] + '...' + mid_rel_types))
KeyError: 'prior_search'
"GET /discover/people/ HTTP/1.1" 500 83367
2023-06-11 09:29:25.936044: ('prior_search',)prior_search queue_mgr.get_queue_list
Internal Server Error: /discover/people/
Traceback (most recent call last):
  File "/home/ed/PycharmProjects/wikidataDiscovery/wd_venv/lib/python3.10/site-packages/django/core/handlers/exception.py", line 56, in inner
    response = get_response(request)
  File "/home/ed/PycharmProjects/wikidataDiscovery/wd_venv/lib/python3.10/site-packages/django/core/handlers/base.py", line 197, in _get_response
    response = wrapped_callback(request, *callback_args, **callback_kwargs)
  File "/home/ed/PycharmProjects/wikidataDiscovery/discover/views.py", line 67, in people
    qf = forms.QueueForm(initial={'facet': Facet.people.value},
  File "/home/ed/PycharmProjects/wikidataDiscovery/discover/forms.py", line 45, in __init__
    self.fields['run_qry'] = forms.ChoiceField(label='Run a previous search',
  File "/home/ed/PycharmProjects/wikidataDiscovery/wd_venv/lib/python3.10/site-packages/django/forms/fields.py", line 862, in __init__
    self.choices = choices
  File "/home/ed/PycharmProjects/wikidataDiscovery/wd_venv/lib/python3.10/site-packages/django/forms/fields.py", line 879, in _set_choices
    value = list(value)
TypeError: 'NoneType' object is not iterable
"GET /discover/people/ HTTP/1.1" 500 89772
2023-06-11 10:24:32.170499: ('prior_search',)prior_search views.search_processed
2023-06-11 10:31:33.004880: ('prior_kw_search',)prior_kw_search queue_mgr.get_queue_list
2023-06-11 10:31:33.005488: ("'NoneType' object is not iterable",)'NoneType' object is not iterable views.search_processed
2023-06-11 10:31:36.001125: ('prior_kw_search',)prior_kw_search queue_mgr.get_queue_list
Internal Server Error: /discover/people/
Traceback (most recent call last):
  File "/home/ed/PycharmProjects/wikidataDiscovery/wd_venv/lib/python3.10/site-packages/django/core/handlers/exception.py", line 56, in inner
    response = get_response(request)
  File "/home/ed/PycharmProjects/wikidataDiscovery/wd_venv/lib/python3.10/site-packages/django/core/handlers/base.py", line 197, in _get_response
    response = wrapped_callback(request, *callback_args, **callback_kwargs)
  File "/home/ed/PycharmProjects/wikidataDiscovery/discover/views.py", line 67, in people
    qf = forms.QueueForm(initial={'facet': Facet.people.value},
  File "/home/ed/PycharmProjects/wikidataDiscovery/discover/forms.py", line 46, in __init__
    self.fields['run_qry'] = forms.ChoiceField(label='Run a previous search',
  File "/home/ed/PycharmProjects/wikidataDiscovery/wd_venv/lib/python3.10/site-packages/django/forms/fields.py", line 862, in __init__
    self.choices = choices
  File "/home/ed/PycharmProjects/wikidataDiscovery/wd_venv/lib/python3.10/site-packages/django/forms/fields.py", line 879, in _set_choices
    value = list(value)
TypeError: 'NoneType' object is not iterable
"GET /discover/people/ HTTP/1.1" 500 89788
2023-06-11 10:33:48.507078: ("local variable 'bottom_search_key' referenced before assignment",)local variable 'bottom_search_key' referenced before assignment queue_mgr.get_queue_list
2023-06-11 10:33:48.507484: ("'NoneType' object is not iterable",)'NoneType' object is not iterable views.search_processed
2023-06-11 10:34:21.457079: ("local variable 'bottom_search_key' referenced before assignment",)local variable 'bottom_search_key' referenced before assignment queue_mgr.get_queue_list
2023-06-11 10:34:21.457688: ("'NoneType' object is not iterable",)'NoneType' object is not iterable views.search_processed
2023-06-12 04:14:57.773607: ("local variable 'bottom_search_key' referenced before assignment",)local variable 'bottom_search_key' referenced before assignment queue_mgr.get_queue_list
2023-06-12 04:14:57.774244: ("'NoneType' object is not iterable",)'NoneType' object is not iterable views.search_processed
2023-06-12 04:15:55.345502: ("local variable 'bottom_search_key' referenced before assignment",)local variable 'bottom_search_key' referenced before assignment queue_mgr.get_queue_list
Internal Server Error: /discover/people/
Traceback (most recent call last):
  File "/home/ed/PycharmProjects/wikidataDiscovery/wd_venv/lib/python3.10/site-packages/django/core/handlers/exception.py", line 56, in inner
    response = get_response(request)
  File "/home/ed/PycharmProjects/wikidataDiscovery/wd_venv/lib/python3.10/site-packages/django/core/handlers/base.py", line 197, in _get_response
    response = wrapped_callback(request, *callback_args, **callback_kwargs)
  File "/home/ed/PycharmProjects/wikidataDiscovery/discover/views.py", line 67, in people
    qf = forms.QueueForm(initial={'facet': Facet.people.value},
  File "/home/ed/PycharmProjects/wikidataDiscovery/discover/forms.py", line 46, in __init__
    self.fields['run_qry'] = forms.ChoiceField(label='Run a previous search',
  File "/home/ed/PycharmProjects/wikidataDiscovery/wd_venv/lib/python3.10/site-packages/django/forms/fields.py", line 862, in __init__
    self.choices = choices
  File "/home/ed/PycharmProjects/wikidataDiscovery/wd_venv/lib/python3.10/site-packages/django/forms/fields.py", line 879, in _set_choices
    value = list(value)
TypeError: 'NoneType' object is not iterable
"GET /discover/people/ HTTP/1.1" 500 89788
2023-06-12 04:19:37.047572: ("local variable 'bottom_search_key' referenced before assignment",)local variable 'bottom_search_key' referenced before assignment queue_mgr.get_queue_list
Internal Server Error: /discover/people/
Traceback (most recent call last):
  File "/home/ed/PycharmProjects/wikidataDiscovery/wd_venv/lib/python3.10/site-packages/django/core/handlers/exception.py", line 56, in inner
    response = get_response(request)
  File "/home/ed/PycharmProjects/wikidataDiscovery/wd_venv/lib/python3.10/site-packages/django/core/handlers/base.py", line 197, in _get_response
    response = wrapped_callback(request, *callback_args, **callback_kwargs)
  File "/home/ed/PycharmProjects/wikidataDiscovery/discover/views.py", line 67, in people
    qf = forms.QueueForm(initial={'facet': Facet.people.value},
  File "/home/ed/PycharmProjects/wikidataDiscovery/discover/forms.py", line 46, in __init__
    self.fields['run_qry'] = forms.ChoiceField(label='Run a previous search',
  File "/home/ed/PycharmProjects/wikidataDiscovery/wd_venv/lib/python3.10/site-packages/django/forms/fields.py", line 862, in __init__
    self.choices = choices
  File "/home/ed/PycharmProjects/wikidataDiscovery/wd_venv/lib/python3.10/site-packages/django/forms/fields.py", line 879, in _set_choices
    value = list(value)
TypeError: 'NoneType' object is not iterable
"GET /discover/people/ HTTP/1.1" 500 89772
2023-06-12 04:30:03.937057: You've used an invalid search string. Try again.1064 views.search_processed
2023-06-12 05:13:48.877345: You've used an invalid search string. Try again.1064 views.search_processed
2023-06-12 06:22:23.982993: ('can only join an iterable',)can only join an iterable views.search_processed
2023-06-12 06:22:57.531928: ('can only join an iterable',)can only join an iterable views.search_processed
2023-06-12 06:36:28.643483: ("'RelationType' object is not iterable",)'RelationType' object is not iterable views.search_processed
2023-06-12 06:36:39.898547: ("'RelationType' object is not iterable",)'RelationType' object is not iterable views.search_processed
2023-06-12 06:37:25.301396: ("'RelationType' object is not subscriptable",)'RelationType' object is not subscriptable views.search_processed
2023-06-12 08:40:49.267696: ('relation_type',)relation_type queue_mgr.get_queue_list
2023-06-12 08:40:49.269299: ("'NoneType' object is not iterable",)'NoneType' object is not iterable views.search_processed
2023-06-12 08:41:21.836729: ('relation_type',)relation_type queue_mgr.get_queue_list
Internal Server Error: /discover/people/
Traceback (most recent call last):
  File "/home/ed/PycharmProjects/wikidataDiscovery/wd_venv/lib/python3.10/site-packages/django/core/handlers/exception.py", line 56, in inner
    response = get_response(request)
  File "/home/ed/PycharmProjects/wikidataDiscovery/wd_venv/lib/python3.10/site-packages/django/core/handlers/base.py", line 197, in _get_response
    response = wrapped_callback(request, *callback_args, **callback_kwargs)
  File "/home/ed/PycharmProjects/wikidataDiscovery/discover/views.py", line 68, in people
    qf = forms.QueueForm(initial={'facet': Facet.people.value},
  File "/home/ed/PycharmProjects/wikidataDiscovery/discover/forms.py", line 48, in __init__
    self.fields['run_qry'] = forms.ChoiceField(label='Run a previous search',
  File "/home/ed/PycharmProjects/wikidataDiscovery/wd_venv/lib/python3.10/site-packages/django/forms/fields.py", line 862, in __init__
    self.choices = choices
  File "/home/ed/PycharmProjects/wikidataDiscovery/wd_venv/lib/python3.10/site-packages/django/forms/fields.py", line 879, in _set_choices
    value = list(value)
TypeError: 'NoneType' object is not iterable
"GET /discover/people/ HTTP/1.1" 500 90338
2023-06-12 08:41:36.913154: ('relation_type',)relation_type queue_mgr.get_queue_list
Internal Server Error: /discover/people/
Traceback (most recent call last):
  File "/home/ed/PycharmProjects/wikidataDiscovery/wd_venv/lib/python3.10/site-packages/django/core/handlers/exception.py", line 56, in inner
    response = get_response(request)
  File "/home/ed/PycharmProjects/wikidataDiscovery/wd_venv/lib/python3.10/site-packages/django/core/handlers/base.py", line 197, in _get_response
    response = wrapped_callback(request, *callback_args, **callback_kwargs)
  File "/home/ed/PycharmProjects/wikidataDiscovery/discover/views.py", line 68, in people
    qf = forms.QueueForm(initial={'facet': Facet.people.value},
  File "/home/ed/PycharmProjects/wikidataDiscovery/discover/forms.py", line 48, in __init__
    self.fields['run_qry'] = forms.ChoiceField(label='Run a previous search',
  File "/home/ed/PycharmProjects/wikidataDiscovery/wd_venv/lib/python3.10/site-packages/django/forms/fields.py", line 862, in __init__
    self.choices = choices
  File "/home/ed/PycharmProjects/wikidataDiscovery/wd_venv/lib/python3.10/site-packages/django/forms/fields.py", line 879, in _set_choices
    value = list(value)
TypeError: 'NoneType' object is not iterable
"GET /discover/people/ HTTP/1.1" 500 90322
Internal Server Error: /discover/people/
Traceback (most recent call last):
  File "/home/ed/PycharmProjects/wikidataDiscovery/wd_venv/lib/python3.10/site-packages/django/core/handlers/exception.py", line 56, in inner
    response = get_response(request)
  File "/home/ed/PycharmProjects/wikidataDiscovery/wd_venv/lib/python3.10/site-packages/django/core/handlers/base.py", line 197, in _get_response
    response = wrapped_callback(request, *callback_args, **callback_kwargs)
  File "/home/ed/PycharmProjects/wikidataDiscovery/discover/views.py", line 67, in people
    the_check = check_set['domain']
TypeError: 'RelationType' object is not subscriptable
"GET /discover/people/ HTTP/1.1" 500 77513
2023-06-12 08:48:55.592224: ('mid',)mid queue_mgr.get_queue_list
2023-06-12 08:48:55.592693: ("'NoneType' object is not iterable",)'NoneType' object is not iterable views.search_processed
2023-06-12 09:09:11.246246: ('mid',)mid queue_mgr.get_queue_list
2023-06-12 09:09:11.246818: ("'NoneType' object is not iterable",)'NoneType' object is not iterable views.search_processed
2023-06-12 09:10:11.780442: ('mid',)mid queue_mgr.get_queue_list
Internal Server Error: /discover/people/
Traceback (most recent call last):
  File "/home/ed/PycharmProjects/wikidataDiscovery/wd_venv/lib/python3.10/site-packages/django/core/handlers/exception.py", line 56, in inner
    response = get_response(request)
  File "/home/ed/PycharmProjects/wikidataDiscovery/wd_venv/lib/python3.10/site-packages/django/core/handlers/base.py", line 197, in _get_response
    response = wrapped_callback(request, *callback_args, **callback_kwargs)
  File "/home/ed/PycharmProjects/wikidataDiscovery/discover/views.py", line 70, in people
    qf = forms.QueueForm(initial={'facet': Facet.people.value},
  File "/home/ed/PycharmProjects/wikidataDiscovery/discover/forms.py", line 48, in __init__
    self.fields['run_qry'] = forms.ChoiceField(label='Run a previous search',
  File "/home/ed/PycharmProjects/wikidataDiscovery/wd_venv/lib/python3.10/site-packages/django/forms/fields.py", line 862, in __init__
    self.choices = choices
  File "/home/ed/PycharmProjects/wikidataDiscovery/wd_venv/lib/python3.10/site-packages/django/forms/fields.py", line 879, in _set_choices
    value = list(value)
TypeError: 'NoneType' object is not iterable
"GET /discover/people/ HTTP/1.1" 500 90488
2023-06-12 09:21:02.952291: ("local variable 'the_checks' referenced before assignment",)local variable 'the_checks' referenced before assignment views.search_processed
2023-06-12 09:27:11.746547: ('mid',)mid queue_mgr.get_queue_list
2023-06-12 09:27:11.747643: ("'NoneType' object is not iterable",)'NoneType' object is not iterable views.search_processed
2023-06-12 09:27:19.599848: ('mid',)mid queue_mgr.get_queue_list
Internal Server Error: /discover/people/
Traceback (most recent call last):
  File "/home/ed/PycharmProjects/wikidataDiscovery/wd_venv/lib/python3.10/site-packages/django/core/handlers/exception.py", line 56, in inner
    response = get_response(request)
  File "/home/ed/PycharmProjects/wikidataDiscovery/wd_venv/lib/python3.10/site-packages/django/core/handlers/base.py", line 197, in _get_response
    response = wrapped_callback(request, *callback_args, **callback_kwargs)
  File "/home/ed/PycharmProjects/wikidataDiscovery/discover/views.py", line 70, in people
    qf = forms.QueueForm(initial={'facet': Facet.people.value},
  File "/home/ed/PycharmProjects/wikidataDiscovery/discover/forms.py", line 48, in __init__
    self.fields['run_qry'] = forms.ChoiceField(label='Run a previous search',
  File "/home/ed/PycharmProjects/wikidataDiscovery/wd_venv/lib/python3.10/site-packages/django/forms/fields.py", line 862, in __init__
    self.choices = choices
  File "/home/ed/PycharmProjects/wikidataDiscovery/wd_venv/lib/python3.10/site-packages/django/forms/fields.py", line 879, in _set_choices
    value = list(value)
TypeError: 'NoneType' object is not iterable
"GET /discover/people/ HTTP/1.1" 500 90488
2023-06-12 09:30:48.511467: ('mid',)mid queue_mgr.get_queue_list
2023-06-12 09:30:48.511889: ("'NoneType' object is not iterable",)'NoneType' object is not iterable views.search_processed
2023-06-12 09:59:33.822596: ('mid',)mid queue_mgr.get_queue_list
Internal Server Error: /discover/people/
Traceback (most recent call last):
  File "/home/ed/PycharmProjects/wikidataDiscovery/wd_venv/lib/python3.10/site-packages/django/core/handlers/exception.py", line 56, in inner
    response = get_response(request)
  File "/home/ed/PycharmProjects/wikidataDiscovery/wd_venv/lib/python3.10/site-packages/django/core/handlers/base.py", line 197, in _get_response
    response = wrapped_callback(request, *callback_args, **callback_kwargs)
  File "/home/ed/PycharmProjects/wikidataDiscovery/discover/views.py", line 70, in people
    qf = forms.QueueForm(initial={'facet': Facet.people.value},
  File "/home/ed/PycharmProjects/wikidataDiscovery/discover/forms.py", line 49, in __init__
    self.fields['run_qry'] = forms.ChoiceField(label='Run a previous search',
  File "/home/ed/PycharmProjects/wikidataDiscovery/wd_venv/lib/python3.10/site-packages/django/forms/fields.py", line 862, in __init__
    self.choices = choices
  File "/home/ed/PycharmProjects/wikidataDiscovery/wd_venv/lib/python3.10/site-packages/django/forms/fields.py", line 879, in _set_choices
    value = list(value)
TypeError: 'NoneType' object is not iterable
"GET /discover/people/ HTTP/1.1" 500 90488
2023-06-12 12:18:41.149193: ('mid',)mid queue_mgr.get_queue_list
2023-06-12 12:18:41.149685: ("'NoneType' object is not iterable",)'NoneType' object is not iterable views.search_processed
2023-06-12 12:19:32.779471: ('mid',)mid queue_mgr.get_queue_list
2023-06-12 12:19:32.780395: ("'NoneType' object is not iterable",)'NoneType' object is not iterable views.search_processed
2023-06-12 12:19:38.976398: ('mid',)mid queue_mgr.get_queue_list
Internal Server Error: /discover/people/
Traceback (most recent call last):
  File "/home/ed/PycharmProjects/wikidataDiscovery/wd_venv/lib/python3.10/site-packages/django/core/handlers/exception.py", line 56, in inner
    response = get_response(request)
  File "/home/ed/PycharmProjects/wikidataDiscovery/wd_venv/lib/python3.10/site-packages/django/core/handlers/base.py", line 197, in _get_response
    response = wrapped_callback(request, *callback_args, **callback_kwargs)
  File "/home/ed/PycharmProjects/wikidataDiscovery/discover/views.py", line 73, in people
    qf = forms.QueueForm(initial={'facet': Facet.people.value},
  File "/home/ed/PycharmProjects/wikidataDiscovery/discover/forms.py", line 49, in __init__
    self.fields['run_qry'] = forms.ChoiceField(label='Run a previous search',
  File "/home/ed/PycharmProjects/wikidataDiscovery/wd_venv/lib/python3.10/site-packages/django/forms/fields.py", line 862, in __init__
    self.choices = choices
  File "/home/ed/PycharmProjects/wikidataDiscovery/wd_venv/lib/python3.10/site-packages/django/forms/fields.py", line 879, in _set_choices
    value = list(value)
TypeError: 'NoneType' object is not iterable
"GET /discover/people/ HTTP/1.1" 500 90072
2023-06-12 12:30:31.960344: ('mid',)mid queue_mgr.get_queue_list
2023-06-12 12:30:31.961474: ("'NoneType' object is not iterable",)'NoneType' object is not iterable views.search_processed
2023-06-12 12:31:00.531966: ('mid',)mid queue_mgr.get_queue_list
Internal Server Error: /discover/people/
Traceback (most recent call last):
  File "/home/ed/PycharmProjects/wikidataDiscovery/wd_venv/lib/python3.10/site-packages/django/core/handlers/exception.py", line 56, in inner
    response = get_response(request)
  File "/home/ed/PycharmProjects/wikidataDiscovery/wd_venv/lib/python3.10/site-packages/django/core/handlers/base.py", line 197, in _get_response
    response = wrapped_callback(request, *callback_args, **callback_kwargs)
  File "/home/ed/PycharmProjects/wikidataDiscovery/discover/views.py", line 73, in people
    qf = forms.QueueForm(initial={'facet': Facet.people.value},
  File "/home/ed/PycharmProjects/wikidataDiscovery/discover/forms.py", line 49, in __init__
    self.fields['run_qry'] = forms.ChoiceField(label='Run a previous search',
  File "/home/ed/PycharmProjects/wikidataDiscovery/wd_venv/lib/python3.10/site-packages/django/forms/fields.py", line 862, in __init__
    self.choices = choices
  File "/home/ed/PycharmProjects/wikidataDiscovery/wd_venv/lib/python3.10/site-packages/django/forms/fields.py", line 879, in _set_choices
    value = list(value)
TypeError: 'NoneType' object is not iterable
"GET /discover/people/ HTTP/1.1" 500 90072
2023-06-12 12:52:07.403210: ('mid',)mid queue_mgr.get_queue_list
2023-06-12 12:52:07.406324: ("'NoneType' object is not iterable",)'NoneType' object is not iterable views.search_processed
Internal Server Error: /discover/subjects/
Traceback (most recent call last):
  File "/home/ed/PycharmProjects/wikidataDiscovery/wd_venv/lib/python3.10/site-packages/django/core/handlers/exception.py", line 56, in inner
    response = get_response(request)
  File "/home/ed/PycharmProjects/wikidataDiscovery/wd_venv/lib/python3.10/site-packages/django/core/handlers/base.py", line 197, in _get_response
    response = wrapped_callback(request, *callback_args, **callback_kwargs)
  File "/home/ed/PycharmProjects/wikidataDiscovery/discover/views.py", line 181, in subjects
    relation = get_default_rel_type(Facet.subjs.value)
  File "/home/ed/PycharmProjects/wikidataDiscovery/discover/views.py", line 447, in get_default_rel_type
    check_set = RelationType.objects.get(domain=facet, list_order=0)
  File "/home/ed/PycharmProjects/wikidataDiscovery/wd_venv/lib/python3.10/site-packages/django/db/models/manager.py", line 85, in manager_method
    return getattr(self.get_queryset(), name)(*args, **kwargs)
  File "/home/ed/PycharmProjects/wikidataDiscovery/wd_venv/lib/python3.10/site-packages/django/db/models/query.py", line 650, in get
    raise self.model.DoesNotExist(
discover.models.RelationType.DoesNotExist: RelationType matching query does not exist.
"GET /discover/subjects/ HTTP/1.1" 500 89412
2023-06-13 04:02:27.378354: ('RelationType matching query does not exist.',)RelationType matching query does not exist. views.search_processed
2023-06-13 04:02:48.201973: ('RelationType matching query does not exist.',)RelationType matching query does not exist. views.search_processed
2023-06-13 04:18:33.094625: ('RelationType matching query does not exist.',)RelationType matching query does not exist. views.search_processed
Internal Server Error: /discover/orals/item/Q111255251/
Traceback (most recent call last):
  File "/home/ed/PycharmProjects/wikidataDiscovery/wd_venv/lib/python3.10/site-packages/django/core/handlers/exception.py", line 56, in inner
    response = get_response(request)
  File "/home/ed/PycharmProjects/wikidataDiscovery/wd_venv/lib/python3.10/site-packages/django/core/handlers/base.py", line 197, in _get_response
    response = wrapped_callback(request, *callback_args, **callback_kwargs)
TypeError: item() got an unexpected keyword argument 'domain'
"GET /discover/orals/item/Q111255251/ HTTP/1.1" 500 72866
2023-06-13 16:20:10.627157: ('top',)top queue_mgr.get_queue_list
2023-06-13 16:20:10.628208: ("'NoneType' object is not iterable",)'NoneType' object is not iterable views.search_processed
2023-06-14 05:01:20.461293: You've used an invalid search string. Try again.1064 views.search_processed
2023-06-14 05:10:38.876747: You've used an invalid search string. Try again.1064 views.search_processed
2023-06-14 05:36:01.666855: ('facet',)facet queue_mgr.create_request
2023-06-14 05:38:19.145618: ('facet',)facet views.search_processed
2023-06-14 05:56:49.083341: ('RelationType matching query does not exist.',)RelationType matching query does not exist. views.search_processed
2023-06-14 06:42:20.318078: You've used an invalid search string. Try again.1064 views.search_processed
2023-06-14 06:46:09.965154: You've used an invalid search string. Try again.1064 views.search_processed
2023-06-14 07:40:19.825746: ('can only concatenate str (not "bool") to str',)can only concatenate str (not "bool") to str views.search_processed
2023-06-14 07:43:56.117340: ('restrict_text',)restrict_text views.search_processed
2023-06-14 07:48:17.558750: ('restrict_text',)restrict_text views.search_processed
2023-06-14 08:09:09.825487: ('restrict_text',)restrict_text views.search_processed
2023-06-14 08:22:29.090897: ('restrict_text',)restrict_text views.search_processed
2023-06-15 06:16:33.138221: ("name 'the_facet' is not defined",)name 'the_facet' is not defined views.search_processed
